Workbook

Sheet Assumptions
A1: ARR Model — Assumptions (blue = editable input)
A3: Essentials ACV — US benchmark ($) | B3: 8000
A4: Growth ACV — US benchmark ($) | B4: 35000
A5: Enterprise ACV — US benchmark ($) | B5: 120000
A6: Annual capture rate (% of addressable) | B6: 0.04
A7: Entry-year ramp (fraction) | B7: 0.5
A8: Net revenue retention (NRR) | B8: 1.12
A11: Market | B11: Accts | C11: Price idx | D11: Mix E | E11: Mix G | F11: Mix Ent | G11: Entry yr | H11: Blended ACV
A12: SEA | B12: 400 | C12: 0.55 | D12: 0.4 | E12: 0.45 | F12: 0.15 | G12: 1 | H12: =C12*(D12*$B$3+E12*$B$4+F12*$B$5) -> 20322.5
A13: India | B13: 500 | C13: 0.45 | D13: 0.55 | E13: 0.35 | F13: 0.1 | G13: 1 | H13: =C13*(D13*$B$3+E13*$B$4+F13*$B$5) -> 12892.5
A14: US | B14: 1200 | C14: 1 | D14: 0.1 | E14: 0.35 | F14: 0.55 | G14: 2 | H14: =C14*(D14*$B$3+E14*$B$4+F14*$B$5) -> 79050
A15: W. Europe | B15: 900 | C15: 0.9 | D15: 0.15 | E15: 0.4 | F15: 0.45 | G15: 3 | H15: =C15*(D15*$B$3+E15*$B$4+F15*$B$5) -> 62280
A16: Japan/Korea | B16: 500 | C16: 0.82 | D16: 0.15 | E16: 0.4 | F16: 0.45 | G16: 3 | H16: =C16*(D16*$B$3+E16*$B$4+F16*$B$5) -> 56744
A18: Note: Ai Palette is private — all values are illustrative, benchmark-anchored assumptions, not reported figures.

Sheet ARR Build
A1: 5-Year ARR Build (live formulas → Assumptions)
A3: SEA
A4: Year | B4: New logos | C4: New ARR | D4: Expansion ARR | E4: End ARR
A5: 1 | B5: =IF(A5<Assumptions!$G$12,0,IF(A5=Assumptions!$G$12,Assumptions!$B$12*Assumptions!$B$6*Assumptions!$B$7,Assumptions!$B$12*Assumptions!$B$6)) -> 8 | C5: =B5*Assumptions!$H$12 -> 162580 | D5: 0 | E5: =C5 -> 162580
A6: 2 | B6: =IF(A6<Assumptions!$G$12,0,IF(A6=Assumptions!$G$12,Assumptions!$B$12*Assumptions!$B$6*Assumptions!$B$7,Assumptions!$B$12*Assumptions!$B$6)) -> 16 | C6: =B6*Assumptions!$H$12 -> 325160 | D6: =E5*(Assumptions!$B$8-1) -> 19509.6 | E6: =E5*Assumptions!$B$8+C6 -> 507249.6
A7: 3 | B7: =IF(A7<Assumptions!$G$12,0,IF(A7=Assumptions!$G$12,Assumptions!$B$12*Assumptions!$B$6*Assumptions!$B$7,Assumptions!$B$12*Assumptions!$B$6)) -> 16 | C7: =B7*Assumptions!$H$12 -> 325160 | D7: =E6*(Assumptions!$B$8-1) -> 60869.952 | E7: =E6*Assumptions!$B$8+C7 -> 893279.55
A8: 4 | B8: =IF(A8<Assumptions!$G$12,0,IF(A8=Assumptions!$G$12,Assumptions!$B$12*Assumptions!$B$6*Assumptions!$B$7,Assumptions!$B$12*Assumptions!$B$6)) -> 16 | C8: =B8*Assumptions!$H$12 -> 325160 | D8: =E7*(Assumptions!$B$8-1) -> 107193.55 | E8: =E7*Assumptions!$B$8+C8 -> 1325633.1
A9: 5 | B9: =IF(A9<Assumptions!$G$12,0,IF(A9=Assumptions!$G$12,Assumptions!$B$12*Assumptions!$B$6*Assumptions!$B$7,Assumptions!$B$12*Assumptions!$B$6)) -> 16 | C9: =B9*Assumptions!$H$12 -> 325160 | D9: =E8*(Assumptions!$B$8-1) -> 159075.97 | E9: =E8*Assumptions!$B$8+C9 -> 1809869.1
A11: India
A12: Year | B12: New logos | C12: New ARR | D12: Expansion ARR | E12: End ARR
A13: 1 | B13: =IF(A13<Assumptions!$G$13,0,IF(A13=Assumptions!$G$13,Assumptions!$B$13*Assumptions!$B$6*Assumptions!$B$7,Assumptions!$B$13*Assumptions!$B$6)) -> 10 | C13: =B13*Assumptions!$H$13 -> 128925 | D13: 0 | E13: =C13 -> 128925
A14: 2 | B14: =IF(A14<Assumptions!$G$13,0,IF(A14=Assumptions!$G$13,Assumptions!$B$13*Assumptions!$B$6*Assumptions!$B$7,Assumptions!$B$13*Assumptions!$B$6)) -> 20 | C14: =B14*Assumptions!$H$13 -> 257850 | D14: =E13*(Assumptions!$B$8-1) -> 15471 | E14: =E13*Assumptions!$B$8+C14 -> 402246
A15: 3 | B15: =IF(A15<Assumptions!$G$13,0,IF(A15=Assumptions!$G$13,Assumptions!$B$13*Assumptions!$B$6*Assumptions!$B$7,Assumptions!$B$13*Assumptions!$B$6)) -> 20 | C15: =B15*Assumptions!$H$13 -> 257850 | D15: =E14*(Assumptions!$B$8-1) -> 48269.52 | E15: =E14*Assumptions!$B$8+C15 -> 708365.52
A16: 4 | B16: =IF(A16<Assumptions!$G$13,0,IF(A16=Assumptions!$G$13,Assumptions!$B$13*Assumptions!$B$6*Assumptions!$B$7,Assumptions!$B$13*Assumptions!$B$6)) -> 20 | C16: =B16*Assumptions!$H$13 -> 257850 | D16: =E15*(Assumptions!$B$8-1) -> 85003.862 | E16: =E15*Assumptions!$B$8+C16 -> 1051219.4
A17: 5 | B17: =IF(A17<Assumptions!$G$13,0,IF(A17=Assumptions!$G$13,Assumptions!$B$13*Assumptions!$B$6*Assumptions!$B$7,Assumptions!$B$13*Assumptions!$B$6)) -> 20 | C17: =B17*Assumptions!$H$13 -> 257850 | D17: =E16*(Assumptions!$B$8-1) -> 126146.33 | E17: =E16*Assumptions!$B$8+C17 -> 1435215.7
A19: US
A20: Year | B20: New logos | C20: New ARR | D20: Expansion ARR | E20: End ARR
A21: 1 | B21: =IF(A21<Assumptions!$G$14,0,IF(A21=Assumptions!$G$14,Assumptions!$B$14*Assumptions!$B$6*Assumptions!$B$7,Assumptions!$B$14*Assumptions!$B$6)) -> 0 | C21: =B21*Assumptions!$H$14 -> 0 | D21: 0 | E21: =C21 -> 0
A22: 2 | B22: =IF(A22<Assumptions!$G$14,0,IF(A22=Assumptions!$G$14,Assumptions!$B$14*Assumptions!$B$6*Assumptions!$B$7,Assumptions!$B$14*Assumptions!$B$6)) -> 24 | C22: =B22*Assumptions!$H$14 -> 1897200 | D22: =E21*(Assumptions!$B$8-1) -> 0 | E22: =E21*Assumptions!$B$8+C22 -> 1897200
A23: 3 | B23: =IF(A23<Assumptions!$G$14,0,IF(A23=Assumptions!$G$14,Assumptions!$B$14*Assumptions!$B$6*Assumptions!$B$7,Assumptions!$B$14*Assumptions!$B$6)) -> 48 | C23: =B23*Assumptions!$H$14 -> 3794400 | D23: =E22*(Assumptions!$B$8-1) -> 227664 | E23: =E22*Assumptions!$B$8+C23 -> 5919264
A24: 4 | B24: =IF(A24<Assumptions!$G$14,0,IF(A24=Assumptions!$G$14,Assumptions!$B$14*Assumptions!$B$6*Assumptions!$B$7,Assumptions!$B$14*Assumptions!$B$6)) -> 48 | C24: =B24*Assumptions!$H$14 -> 3794400 | D24: =E23*(Assumptions!$B$8-1) -> 710311.68 | E24: =E23*Assumptions!$B$8+C24 -> 10423976
A25: 5 | B25: =IF(A25<Assumptions!$G$14,0,IF(A25=Assumptions!$G$14,Assumptions!$B$14*Assumptions!$B$6*Assumptions!$B$7,Assumptions!$B$14*Assumptions!$B$6)) -> 48 | C25: =B25*Assumptions!$H$14 -> 3794400 | D25: =E24*(Assumptions!$B$8-1) -> 1250877.1 | E25: =E24*Assumptions!$B$8+C25 -> 15469253
A27: W. Europe
A28: Year | B28: New logos | C28: New ARR | D28: Expansion ARR | E28: End ARR
A29: 1 | B29: =IF(A29<Assumptions!$G$15,0,IF(A29=Assumptions!$G$15,Assumptions!$B$15*Assumptions!$B$6*Assumptions!$B$7,Assumptions!$B$15*Assumptions!$B$6)) -> 0 | C29: =B29*Assumptions!$H$15 -> 0 | D29: 0 | E29: =C29 -> 0
A30: 2 | B30: =IF(A30<Assumptions!$G$15,0,IF(A30=Assumptions!$G$15,Assumptions!$B$15*Assumptions!$B$6*Assumptions!$B$7,Assumptions!$B$15*Assumptions!$B$6)) -> 0 | C30: =B30*Assumptions!$H$15 -> 0 | D30: =E29*(Assumptions!$B$8-1) -> 0 | E30: =E29*Assumptions!$B$8+C30 -> 0
A31: 3 | B31: =IF(A31<Assumptions!$G$15,0,IF(A31=Assumptions!$G$15,Assumptions!$B$15*Assumptions!$B$6*Assumptions!$B$7,Assumptions!$B$15*Assumptions!$B$6)) -> 18 | C31: =B31*Assumptions!$H$15 -> 1121040 | D31: =E30*(Assumptions!$B$8-1) -> 0 | E31: =E30*Assumptions!$B$8+C31 -> 1121040
A32: 4 | B32: =IF(A32<Assumptions!$G$15,0,IF(A32=Assumptions!$G$15,Assumptions!$B$15*Assumptions!$B$6*Assumptions!$B$7,Assumptions!$B$15*Assumptions!$B$6)) -> 36 | C32: =B32*Assumptions!$H$15 -> 2242080 | D32: =E31*(Assumptions!$B$8-1) -> 134524.8 | E32: =E31*Assumptions!$B$8+C32 -> 3497644.8
A33: 5 | B33: =IF(A33<Assumptions!$G$15,0,IF(A33=Assumptions!$G$15,Assumptions!$B$15*Assumptions!$B$6*Assumptions!$B$7,Assumptions!$B$15*Assumptions!$B$6)) -> 36 | C33: =B33*Assumptions!$H$15 -> 2242080 | D33: =E32*(Assumptions!$B$8-1) -> 419717.38 | E33: =E32*Assumptions!$B$8+C33 -> 6159442.2
A35: Japan/Korea
A36: Year | B36: New logos | C36: New ARR | D36: Expansion ARR | E36: End ARR
A37: 1 | B37: =IF(A37<Assumptions!$G$16,0,IF(A37=Assumptions!$G$16,Assumptions!$B$16*Assumptions!$B$6*Assumptions!$B$7,Assumptions!$B$16*Assumptions!$B$6)) -> 0 | C37: =B37*Assumptions!$H$16 -> 0 | D37: 0 | E37: =C37 -> 0
A38: 2 | B38: =IF(A38<Assumptions!$G$16,0,IF(A38=Assumptions!$G$16,Assumptions!$B$16*Assumptions!$B$6*Assumptions!$B$7,Assumptions!$B$16*Assumptions!$B$6)) -> 0 | C38: =B38*Assumptions!$H$16 -> 0 | D38: =E37*(Assumptions!$B$8-1) -> 0 | E38: =E37*Assumptions!$B$8+C38 -> 0
A39: 3 | B39: =IF(A39<Assumptions!$G$16,0,IF(A39=Assumptions!$G$16,Assumptions!$B$16*Assumptions!$B$6*Assumptions!$B$7,Assumptions!$B$16*Assumptions!$B$6)) -> 10 | C39: =B39*Assumptions!$H$16 -> 567440 | D39: =E38*(Assumptions!$B$8-1) -> 0 | E39: =E38*Assumptions!$B$8+C39 -> 567440
A40: 4 | B40: =IF(A40<Assumptions!$G$16,0,IF(A40=Assumptions!$G$16,Assumptions!$B$16*Assumptions!$B$6*Assumptions!$B$7,Assumptions!$B$16*Assumptions!$B$6)) -> 20 | C40: =B40*Assumptions!$H$16 -> 1134880 | D40: =E39*(Assumptions!$B$8-1) -> 68092.8 | E40: =E39*Assumptions!$B$8+C40 -> 1770412.8
A41: 5 | B41: =IF(A41<Assumptions!$G$16,0,IF(A41=Assumptions!$G$16,Assumptions!$B$16*Assumptions!$B$6*Assumptions!$B$7,Assumptions!$B$16*Assumptions!$B$6)) -> 20 | C41: =B41*Assumptions!$H$16 -> 1134880 | D41: =E40*(Assumptions!$B$8-1) -> 212449.54 | E41: =E40*Assumptions!$B$8+C41 -> 3117742.3
A44: TOTAL ARR (all markets)
A45: Year | E45: Total End ARR
A46: 1 | E46: =E5+E13+E21+E29+E37 -> 291505
A47: 2 | E47: =E6+E14+E22+E30+E38 -> 2806695.6
...
